 Preparing metadata (setup.py) ... error
  error: subprocess-exited-with-error

  × python setup.py egg_info did not run successfully.
  │ exit code: 1
  ╰─> [48 lines of output]
      Traceback (most recent call last):
        File "<string>", line 2, in <module>
          exec(compile('''
          ~~~~^^^^^^^^^^^^
          # This is <pip-setuptools-caller> -- a caller that pip uses to run setup.py
          ^^^^^^^^^^^^^^^^^^^^^^^^^^^^^^^^^^^^^^^^^^^^^^^^^^^^^^^^^^^^^^^^^^^^^^^^^^^
          ...<32 lines>...
          exec(compile(setup_py_code, filename, "exec"))
          ^^^^^^^^^^^^^^^^^^^^^^^^^^^^^^^^^^^^^^^^^^^^^^
          ''' % ('C:\\Users\\alish.VICTUS\\AppData\\Local\\Temp\\pip-install-pqsacn6z\\sentencepiece_ba45e85869b045388eb45de8525cdb44\\setup.py',), "<pip-setuptools-caller>", "exec"))
          ^^^^^^^^^^^^^^^^^^^^^^^^^^^^^^^^^^^^^^^^^^^^^^^^^^^^^^^^^^^^^^^^^^^^^^^^^^^^^^^^^^^^^^^^^^^^^^^^^^^^^^^^^^^^^^^^^^^^^^^^^^^^^^^^^^^^^^^^^^^^^^^^^^^^^^^^^^^^^^^^^^^^^^^^^^^^^
        File "<pip-setuptools-caller>", line 35, in <module>
        File "C:\Users\alish.VICTUS\AppData\Local\Temp\pip-install-pqsacn6z\sentencepiece_ba45e85869b045388eb45de8525cdb44\setup.py", line 128, in <module>
          subprocess.check_call([
          ~~~~~~~~~~~~~~~~~~~~~^^
              'cmake',
              ^^^^^^^^
          ...<6 lines>...
              '-DCMAKE_INSTALL_PREFIX=build\\root',
              ^^^^^^^^^^^^^^^^^^^^^^^^^^^^^^^^^^^^^
          ])
          ^^
        File "C:\Program Files\WindowsApps\PythonSoftwareFoundation.Python.3.13_3.13.752.0_x64__qbz5n2kfra8p0\Lib\subprocess.py", line 416, in check_call
          retcode = call(*popenargs, **kwargs)
        File "C:\Program Files\WindowsApps\PythonSoftwareFoundation.Python.3.13_3.13.752.0_x64__qbz5n2kfra8p0\Lib\subprocess.py", line 397, in call
          with Popen(*popenargs, **kwargs) as p:
               ~~~~~^^^^^^^^^^^^^^^^^^^^^^
        File "C:\Program Files\WindowsApps\PythonSoftwareFoundation.Python.3.13_3.13.752.0_x64__qbz5n2kfra8p0\Lib\subprocess.py", line 1038, in __init__
          self._execute_child(args, executable, preexec_fn, close_fds,
          ~~~~~~~~~~~~~~~~~~~^^^^^^^^^^^^^^^^^^^^^^^^^^^^^^^^^^^^^^^^^
                              pass_fds, cwd, env,
                              ^^^^^^^^^^^^^^^^^^^
          ...<5 lines>...
                              gid, gids, uid, umask,
                              ^^^^^^^^^^^^^^^^^^^^^^
                              start_new_session, process_group)
                              ^^^^^^^^^^^^^^^^^^^^^^^^^^^^^^^^^
        File "C:\Program Files\WindowsApps\PythonSoftwareFoundation.Python.3.13_3.13.752.0_x64__qbz5n2kfra8p0\Lib\subprocess.py", line 1550, in _execute_child
          hp, ht, pid, tid = _winapi.CreateProcess(executable, args,
                             ~~~~~~~~~~~~~~~~~~~~~^^^^^^^^^^^^^^^^^^
                                   # no special security
                                   ^^^^^^^^^^^^^^^^^^^^^
          ...<4 lines>...
                                   cwd,
                                   ^^^^
                                   startupinfo)
                                   ^^^^^^^^^^^^
      FileNotFoundError: [WinError 2] The system cannot find the file specified
      [end of output]

  note: This error originates from a subprocess, and is likely not a problem with pip.
error: metadata-generation-failed

× Encountered error while generating package metadata.
╰─> See above for output.

note: This is an issue with the package mentioned above, not pip.
hint: See above for details.
PS C:\_worxpace\artifactvirtual> 